[2025-06-23T12:32:11.408+0000] {taskinstance.py:1159} INFO - Dependencies all met for dep_context=non-requeueable deps ti=<TaskInstance: Airflow_ETL_DAG_with_Population.insert_viruses scheduled__2025-03-10T00:00:00+00:00 [queued]>
[2025-06-23T12:32:11.416+0000] {taskinstance.py:1159} INFO - Dependencies all met for dep_context=requeueable deps ti=<TaskInstance: Airflow_ETL_DAG_with_Population.insert_viruses scheduled__2025-03-10T00:00:00+00:00 [queued]>
[2025-06-23T12:32:11.417+0000] {taskinstance.py:1361} INFO - Starting attempt 1 of 2
[2025-06-23T12:32:11.429+0000] {taskinstance.py:1382} INFO - Executing <Task(PythonOperator): insert_viruses> on 2025-03-10 00:00:00+00:00
[2025-06-23T12:32:11.435+0000] {standard_task_runner.py:57} INFO - Started process 237 to run task
[2025-06-23T12:32:11.438+0000] {standard_task_runner.py:84} INFO - Running: ['airflow', 'tasks', 'run', 'Airflow_ETL_DAG_with_Population', 'insert_viruses', 'scheduled__2025-03-10T00:00:00+00:00', '--job-id', '4', '--raw', '--subdir', 'DAGS_FOLDER/airflow_etl.py', '--cfg-path', '/tmp/tmpcvo9yox5']
[2025-06-23T12:32:11.440+0000] {standard_task_runner.py:85} INFO - Job 4: Subtask insert_viruses
[2025-06-23T12:32:11.486+0000] {task_command.py:416} INFO - Running <TaskInstance: Airflow_ETL_DAG_with_Population.insert_viruses scheduled__2025-03-10T00:00:00+00:00 [running]> on host efd474e5dada
[2025-06-23T12:32:11.562+0000] {taskinstance.py:1662} INFO - Exporting env vars: AIRFLOW_CTX_DAG_OWNER='airflow' AIRFLOW_CTX_DAG_ID='Airflow_ETL_DAG_with_Population' AIRFLOW_CTX_TASK_ID='insert_viruses' AIRFLOW_CTX_EXECUTION_DATE='2025-03-10T00:00:00+00:00' AIRFLOW_CTX_TRY_NUMBER='1' AIRFLOW_CTX_DAG_RUN_ID='scheduled__2025-03-10T00:00:00+00:00'
[2025-06-23T12:32:11.784+0000] {logging_mixin.py:151} INFO - Table utilisée: pandemics.virus
[2025-06-23T12:32:11.794+0000] {logging_mixin.py:151} INFO - Erreur dans task_insert_viruses: (psycopg2.errors.UniqueViolation) duplicate key value violates unique constraint "virus_pkey"
DETAIL:  Key (id)=(1) already exists.

[SQL: INSERT INTO pandemics.virus (id, name) VALUES (%(id)s, %(name)s)]
[parameters: {'id': 1, 'name': 'Monkeypox'}]
(Background on this error at: https://sqlalche.me/e/14/gkpj)
[2025-06-23T12:32:11.795+0000] {taskinstance.py:1937} ERROR - Task failed with exception
Traceback (most recent call last):
  File "/home/airflow/.local/lib/python3.8/site-packages/sqlalchemy/engine/base.py", line 1910, in _execute_context
    self.dialect.do_execute(
  File "/home/airflow/.local/lib/python3.8/site-packages/sqlalchemy/engine/default.py", line 736, in do_execute
    cursor.execute(statement, parameters)
psycopg2.errors.UniqueViolation: duplicate key value violates unique constraint "virus_pkey"
DETAIL:  Key (id)=(1) already exists.


The above exception was the direct cause of the following exception:

Traceback (most recent call last):
  File "/home/airflow/.local/lib/python3.8/site-packages/airflow/operators/python.py", line 192, in execute
    return_value = self.execute_callable()
  File "/home/airflow/.local/lib/python3.8/site-packages/airflow/operators/python.py", line 209, in execute_callable
    return self.python_callable(*self.op_args, **self.op_kwargs)
  File "/opt/airflow/dags/airflow_etl.py", line 142, in task_insert_viruses
    session.execute(ins)
  File "/home/airflow/.local/lib/python3.8/site-packages/sqlalchemy/orm/session.py", line 1717, in execute
    result = conn._execute_20(statement, params or {}, execution_options)
  File "/home/airflow/.local/lib/python3.8/site-packages/sqlalchemy/engine/base.py", line 1710, in _execute_20
    return meth(self, args_10style, kwargs_10style, execution_options)
  File "/home/airflow/.local/lib/python3.8/site-packages/sqlalchemy/sql/elements.py", line 334, in _execute_on_connection
    return connection._execute_clauseelement(
  File "/home/airflow/.local/lib/python3.8/site-packages/sqlalchemy/engine/base.py", line 1577, in _execute_clauseelement
    ret = self._execute_context(
  File "/home/airflow/.local/lib/python3.8/site-packages/sqlalchemy/engine/base.py", line 1953, in _execute_context
    self._handle_dbapi_exception(
  File "/home/airflow/.local/lib/python3.8/site-packages/sqlalchemy/engine/base.py", line 2134, in _handle_dbapi_exception
    util.raise_(
  File "/home/airflow/.local/lib/python3.8/site-packages/sqlalchemy/util/compat.py", line 211, in raise_
    raise exception
  File "/home/airflow/.local/lib/python3.8/site-packages/sqlalchemy/engine/base.py", line 1910, in _execute_context
    self.dialect.do_execute(
  File "/home/airflow/.local/lib/python3.8/site-packages/sqlalchemy/engine/default.py", line 736, in do_execute
    cursor.execute(statement, parameters)
sqlalchemy.exc.IntegrityError: (psycopg2.errors.UniqueViolation) duplicate key value violates unique constraint "virus_pkey"
DETAIL:  Key (id)=(1) already exists.

[SQL: INSERT INTO pandemics.virus (id, name) VALUES (%(id)s, %(name)s)]
[parameters: {'id': 1, 'name': 'Monkeypox'}]
(Background on this error at: https://sqlalche.me/e/14/gkpj)
[2025-06-23T12:32:11.824+0000] {taskinstance.py:1400} INFO - Marking task as UP_FOR_RETRY. dag_id=Airflow_ETL_DAG_with_Population, task_id=insert_viruses, execution_date=20250310T000000, start_date=20250623T123211, end_date=20250623T123211
[2025-06-23T12:32:11.840+0000] {standard_task_runner.py:104} ERROR - Failed to execute job 4 for task insert_viruses ((psycopg2.errors.UniqueViolation) duplicate key value violates unique constraint "virus_pkey"
DETAIL:  Key (id)=(1) already exists.

[SQL: INSERT INTO pandemics.virus (id, name) VALUES (%(id)s, %(name)s)]
[parameters: {'id': 1, 'name': 'Monkeypox'}]
(Background on this error at: https://sqlalche.me/e/14/gkpj); 237)
[2025-06-23T12:32:11.851+0000] {local_task_job_runner.py:228} INFO - Task exited with return code 1
[2025-06-23T12:32:11.879+0000] {taskinstance.py:2778} INFO - 0 downstream tasks scheduled from follow-on schedule check
[2025-06-23T12:45:41.445+0000] {taskinstance.py:1159} INFO - Dependencies all met for dep_context=non-requeueable deps ti=<TaskInstance: Airflow_ETL_DAG_with_Population.insert_viruses scheduled__2025-03-10T00:00:00+00:00 [queued]>
[2025-06-23T12:45:41.458+0000] {taskinstance.py:1159} INFO - Dependencies all met for dep_context=requeueable deps ti=<TaskInstance: Airflow_ETL_DAG_with_Population.insert_viruses scheduled__2025-03-10T00:00:00+00:00 [queued]>
[2025-06-23T12:45:41.459+0000] {taskinstance.py:1361} INFO - Starting attempt 1 of 2
[2025-06-23T12:45:41.470+0000] {taskinstance.py:1382} INFO - Executing <Task(PythonOperator): insert_viruses> on 2025-03-10 00:00:00+00:00
[2025-06-23T12:45:41.477+0000] {standard_task_runner.py:57} INFO - Started process 203 to run task
[2025-06-23T12:45:41.480+0000] {standard_task_runner.py:84} INFO - Running: ['airflow', 'tasks', 'run', 'Airflow_ETL_DAG_with_Population', 'insert_viruses', 'scheduled__2025-03-10T00:00:00+00:00', '--job-id', '3', '--raw', '--subdir', 'DAGS_FOLDER/airflow_etl.py', '--cfg-path', '/tmp/tmp43c8yd4_']
[2025-06-23T12:45:41.482+0000] {standard_task_runner.py:85} INFO - Job 3: Subtask insert_viruses
[2025-06-23T12:45:41.528+0000] {task_command.py:416} INFO - Running <TaskInstance: Airflow_ETL_DAG_with_Population.insert_viruses scheduled__2025-03-10T00:00:00+00:00 [running]> on host e9b9727fd2b0
[2025-06-23T12:45:41.646+0000] {taskinstance.py:1662} INFO - Exporting env vars: AIRFLOW_CTX_DAG_OWNER='airflow' AIRFLOW_CTX_DAG_ID='Airflow_ETL_DAG_with_Population' AIRFLOW_CTX_TASK_ID='insert_viruses' AIRFLOW_CTX_EXECUTION_DATE='2025-03-10T00:00:00+00:00' AIRFLOW_CTX_TRY_NUMBER='1' AIRFLOW_CTX_DAG_RUN_ID='scheduled__2025-03-10T00:00:00+00:00'
[2025-06-23T12:45:41.863+0000] {logging_mixin.py:151} INFO - Table utilisée: pandemics.virus
[2025-06-23T12:45:41.909+0000] {logging_mixin.py:151} INFO - Insertion des virus terminée.
[2025-06-23T12:45:41.910+0000] {python.py:194} INFO - Done. Returned value was: None
[2025-06-23T12:45:41.919+0000] {taskinstance.py:1400} INFO - Marking task as SUCCESS. dag_id=Airflow_ETL_DAG_with_Population, task_id=insert_viruses, execution_date=20250310T000000, start_date=20250623T124541, end_date=20250623T124541
[2025-06-23T12:45:41.975+0000] {local_task_job_runner.py:228} INFO - Task exited with return code 0
[2025-06-23T12:45:41.994+0000] {taskinstance.py:2778} INFO - 1 downstream tasks scheduled from follow-on schedule check
